<?xml version="1.0" ?>
<robot
  name="turtlebotmini">


<!--  <link name="base_footprint"/>

  <joint name="base_joint" type="fixed">
    <parent link="base_footprint"/>
    <child link="base_link"/>
    <origin xyz="0.0 0.0 0.010" rpy="0 0 0"/>
  </joint>-->


  <link
    name="base_link">
    <inertial>
      <origin
        xyz="0.0011869 -0.007673 0.12049"
        rpy="0 0 0" />
      <mass
        value="10.0" />
      <inertia
        ixx="0.01"
        ixy="0.0"
        ixz="0.0"
        iyy="0.01"
        iyz="0.0"
        izz="0.01" />
    </inertial>
    <visual>
      <origin
        xyz="0 0 0"
        rpy="0 0 0" />
      <geometry>
        <mesh
          filename="package://minimapping/meshes/base_link.stl" />
      </geometry>
      <material
        name="">
        <color
          rgba="0.25098 0.25098 0.25098 1" />
      </material>
    </visual>
    <collision>
      <origin
        xyz="0 0 0"
        rpy="0 0 0" />
      <geometry>
        <mesh
          filename="package://minimapping/meshes/base_link.stl" />
      </geometry>
    </collision>
  </link>
  <link
    name="wheel_left_link">
    <inertial>
      <origin
        xyz="0.0069553 1.1547E-06 -2.619E-07"
        rpy="0 0 0" />
      <mass
        value="0.012859" />
        <inertia
          ixx="0.001"
          ixy="0.0"
          ixz="0.0"
          iyy="0.001"
          iyz="0.0"
          izz="0.001" />
    </inertial>
    <visual>
      <origin
        xyz="0 0 0"
        rpy="0 0 0" />
      <geometry>
        <mesh
          filename="package://minimapping/meshes/wheel_left_link.stl" />
      </geometry>
      <material
        name="">
        <color
          rgba="0.79216 0.81961 0.93333 1" />
      </material>
    </visual>
    <collision>
      <origin
        xyz="0 0 0"
        rpy="0 0 0" />
      <geometry>
        <mesh
          filename="package://minimapping/meshes/wheel_left_link.stl" />
      </geometry>
    </collision>
  </link>
  <joint
    name="wheel_left_joint"
    type="continuous">
    <origin
      xyz="0.063388 0 0.035"
      rpy="1.5708 0 0" />
    <parent
      link="base_link" />
    <child
      link="wheel_left_link" />
    <axis
      xyz="1 0 0" />
  </joint>
  <link
    name="wheel_right_link">
    <inertial>
      <origin
        xyz="0.0069553 1.1547E-06 -2.619E-07"
        rpy="0 0 0" />
      <mass
        value="0.012859" />
        <inertia
          ixx="0.001"
          ixy="0.0"
          ixz="0.0"
          iyy="0.001"
          iyz="0.0"
          izz="0.001" />
    </inertial>
    <visual>
      <origin
        xyz="0 0 0"
        rpy="0 0 0" />
      <geometry>
        <mesh
          filename="package://minimapping/meshes/wheel_right_link.stl" />
      </geometry>
      <material
        name="">
        <color
          rgba="0.79216 0.81961 0.93333 1" />
      </material>
    </visual>
    <collision>
      <origin
        xyz="0 0 0"
        rpy="0 0 0" />
      <geometry>
        <mesh
          filename="package://minimapping/meshes/wheel_right_link.stl" />
      </geometry>
    </collision>
  </link>
  <joint
    name="wheel_right_joint"
    type="continuous">
    <origin
      xyz="-0.063388 0 0.035"
      rpy="2.7498 0 3.1416" />
    <parent
      link="base_link" />
    <child
      link="wheel_right_link" />
    <axis
      xyz="-1 0 0" />
  </joint>


<link name="caster_front_link">
   <visual>
     <geometry>
       <sphere radius="0.0127"/>
     </geometry>
     <material name="red"/>
   </visual>
   <inertial>
     <origin xyz="0 0 0" />
     <mass value="0.01" />
     <inertia ixx="0.001" ixy="0.0" ixz="0.0"
              iyy="0.001" iyz="0.0"
              izz="0.001" />
   </inertial>
 </link>

 <joint name="caster_front_joint" type="fixed">
   <parent link="base_link"/>
   <child link="caster_front_link"/>
   <origin xyz="0 -0.0445 0.0128"/>
 </joint>

<link name="caster_back_link">
   <visual>
     <geometry>
       <sphere radius="0.0127"/>
     </geometry>
     <material name="red"/>
   </visual>
   <inertial>
     <origin xyz="0 0 0" />
     <mass value="0.01" />
     <inertia ixx="0.001" ixy="0.0" ixz="0.0"
              iyy="0.001" iyz="0.0"
              izz="0.001" />
   </inertial>
 </link>

 <joint name="caster_back_joint" type="fixed">
   <parent link="base_link"/>
   <child link="caster_back_link"/>
   <origin xyz="0 0.064 0.0128"/>
 </joint>

<joint name="hokuyo_joint" type="fixed">
  <axis xyz="0 1 0" />
  <origin xyz="0.0 0.0 0.241" rpy="0 0 -1.5707963"/>  <!-- Z: 0.241 -->
  <parent link="base_link"/>
  <child link="hokuyo_link"/>
</joint>

<!-- Hokuyo Laser -->
<link name="hokuyo_link">
  <collision>
    <origin xyz="0 0 0" rpy="0 0 0"/>
    <geometry>
    <box size="0.1 0.1 0.1"/>
    </geometry>
  </collision>

  <visual>
    <origin xyz="0 0 0" rpy="0 0 0"/>
    <geometry>
    <box size="0.01 0.01 0.01" />
<!--      <mesh filename="package://minimapping/meshes/hokuyo.dae"/> -->
    </geometry>
  </visual>

  <inertial>
    <mass value="1e-5" />
    <origin xyz="0 0 0" rpy="0 0 0"/>
    <inertia ixx="1e-6" ixy="0" ixz="0" iyy="1e-6" iyz="0" izz="1e-6" />
  </inertial>
</link>


</robot>
